Workbook

Sheet 1. Cover & Assumptions
A1: TYLER COFL TEAM - 'IS IT WORTH IT?' PROFORMA & FORECAST
A2: Texas Continental Football League (CoFL) - Tyler Franchise
A3: Prepared: April 28, 2026 | Home venue: CHRISTUS TMF Rose Stadium
A5: PROJECT OVERVIEW
A6: Project: | B6: Stand up a Texas Continental Football League (CoFL) franchise based in Tyler, TX.
A7: Home venue: | B7: CHRISTUS Trinity Mother Frances Rose Stadium (Tyler ISD)
A8: Stadium capacity: | B8: 10,566 (per Tyler ISD facility listing)
A9: Year 1 home games modeled: | B9: 3 (per existing breakeven workbook)
A10: Anchor sponsor target: | B10: CHRISTUS Health (naming-rights aligned with stadium sponsor)
A11: Funding mechanism: | B11: WeFunder Reg CF community equity campaign + tier sponsorships
A12: Growth assumption: | B12: 10% annual top-line growth (per conversations with Manny)
A14: KEY GLOBAL ASSUMPTIONS (BLUE = inputs you can change)
A15: Assumption | B15: Value | C15: Unit | D15: Notes / Source
A16: Annual top-line revenue growth | B16: 0.1 | D16: Per Manny - 10% YoY growth assumption
A17: Annual expense inflation | B17: 0.04 | D17: General CPI / wage inflation placeholder
A18: Home games / season (Yr 1) | B18: 3 | D18: Per existing breakeven workbook
A19: Home games / season (Yr 5+) | B19: 5 | D19: Schedule expansion as league matures
A20: Stadium max capacity | B20: 10566 | D20: CHRISTUS TMF Rose Stadium
A21: Year 1 average attendance / game | B21: 1875 | D21: Per existing breakeven model (~17.7% of capacity)
A22: Annual franchise fee (CoFL HQ) | B22: 50000 | D22: Per user instruction
A23: Legal & accounting setup (one-time) | B23: 7500 | D23: Midpoint of $5K-$10K range provided
A24: Smith County population | B24: 245000 | D24: TX Demographic Center est.
A25: East Texas catchment population | B25: 762000 | D25: Smith + Gregg + Henderson + Cherokee + Van Zandt + Rusk + Wood + Anderson + Upshur counties
A26: Tyler MSA population | B26: 240000 | D26: Tyler Metro Statistical Area
A29: ROSE STADIUM - INFORMATION FROM SCHOOLSPACE LISTING
A30: Item | B30: Rate / Detail
A31: Facility name | B31: CHRISTUS TMF Rose Stadium
A32: Owner / Operator | B32: Tyler Independent School District
A33: Max capacity | B33: 10,566
A34: Non-football activity rate (4-hr min) | B34: $500 / hour
A35: Additional hours rate | B35: $200 / hour
A36: Video board use | B36: $1,000 flat fee
A37: Field supervisor | B37: $25 / hr (3-hr min)
A38: Custodian | B38: $25 / hr (3-hr min)
A39: Security (per officer) | B39: $30 / hr (3-hr min)
A40: Concessions | B40: Tyler ISD has 1st right; if declined, $250/day to renter
A41: CRITICAL CALENDAR CAVEAT | B41: Rose Stadium NOT available during Tyler ISD football season (Aug-Nov)

Sheet 2. Initial Investment
A1: INITIAL INVESTMENT - YEAR 0 / PRE-LAUNCH CAPITAL REQUIRED
A3: One-time costs to stand up the franchise BEFORE first game.
A5: ONE-TIME STARTUP COSTS
A6: Cost Category | B6: Low | C6: High | D6: Midpoint (used) | E6: Notes
A7: CoFL Franchise entry fee (one-time, est.) | B7: 25000 | C7: 50000 | D7: =AVERAGE(B7:C7) -> 37500 | E7: Estimate; confirm with league office; separate from $50K annual
A8: Legal setup (LLC, contracts, IP, league agreements) | B8: 5000 | C8: 10000 | D8: =AVERAGE(B8:C8) -> 7500 | E8: Per user instruction ($5K-$10K)
A9: Accounting setup (chart of accounts, payroll, books) | B9: 3000 | C9: 5000 | D9: =AVERAGE(B9:C9) -> 4000 | E9: Initial accounting infrastructure
A10: Insurance binding & annual prepay (GL, D&O, accident) | B10: 25000 | C10: 50000 | D10: =AVERAGE(B10:C10) -> 37500 | E10: Liability + accident coverage for players & spectators
A11: Branding / Identity (logo, mark, trademark search) | B11: 8000 | C11: 20000 | D11: =AVERAGE(B11:C11) -> 14000 | E11: Pro design + USPTO trademark filing
A12: Website + ticketing platform setup | B12: 8000 | C12: 15000 | D12: =AVERAGE(B12:C12) -> 11500 | E12: Site, e-commerce, ticketing integration
A13: Equipment - Helmets (50 @ $500) | B13: 25000 | C13: 25000 | D13: =AVERAGE(B13:C13) -> 25000 | E13: Per breakeven workbook
A14: Equipment - Shoulder pads (50 @ $300) | B14: 15000 | C14: 15000 | D14: =AVERAGE(B14:C14) -> 15000 | E14: Per breakeven workbook
A15: Equipment - Practice gear, sleds, blocking dummies | B15: 15000 | C15: 30000 | D15: =AVERAGE(B15:C15) -> 22500 | E15: Practice infrastructure
A16: Game uniforms (2 sets, 50 players) | B16: 17500 | C16: 17500 | D16: =AVERAGE(B16:C16) -> 17500 | E16: Per breakeven workbook
A17: Practice uniforms (1 set, 50 players) | B17: 4000 | C17: 4000 | D17: =AVERAGE(B17:C17) -> 4000 | E17: Per breakeven workbook
A18: Office setup (computers, software, furniture) | B18: 10000 | C18: 25000 | D18: =AVERAGE(B18:C18) -> 17500 | E18: Front office infrastructure
... A22: Working capital reserve (3 months opex) | B22: 100000 | C22: 200000 | D22: =AVERAGE(B22:C22) -> 150000 | E22: Cash buffer through first season
A23: TOTAL INITIAL INVESTMENT REQUIRED | B23: =SUM(B7:B22) -> 295500 | C23: =SUM(C7:C22) -> 536500 | D23: =SUM(D7:D22) -> 416000
A25: FUNDING SOURCES
A26: Source | B26: Amount | C26: % | D26: Notes
A27: WeFunder Reg CF community campaign | B27: 100000 | C27: =B27/$B$32 -> 0.17241379 | D27: Per existing breakeven workbook ($1K avg x 100 investors)
A28: Founding / Title sponsor (CHRISTUS Health target) | B28: 150000 | C28: =B28/$B$32 -> 0.25862069 | D28: Multi-year naming-rights aligned with stadium sponsor
A29: Founder equity / lead investors | B29: 250000 | C29: =B29/$B$32 -> 0.43103448 | D29: Anchor capital from ownership group
A30: Tier sponsorships pre-sold | B30: 80000 | C30: =B30/$B$32 -> 0.13793103 | D30: Bronze/Silver tier presales
A31: Bridge / line of credit (if needed) | B31: 0 | C31: =B31/$B$32 -> 0 | D31: Backstop only - prefer not to use
A32: TOTAL FUNDING | B32: =SUM(B27:B31) -> 580000
A34: Funding gap / (surplus) vs. required investment | B34: =D23-B32 -> -164000

Sheet 3. Rose Stadium Detail
A1: ROSE STADIUM - PER-GAME COST BUILD-UP
A3: Replaces the $1,000/game 'Home Game Facility Fee' placeholder in the original breakeven workbook.
A5: PER-GAME RENTAL COST
A6: Line Item | B6: Hours / Qty | C6: Rate | D6: Subtotal | E6: Per Season (3 games) | F6: Notes
A7: Stadium base rate (4-hr minimum) | B7: 4 | C7: 500 | D7: =B7*C7 -> 2000 | E7: =D7*'1. Cover & Assumptions'!$B$18 -> 6000 | F7: $500/hr, 4-hr min per SchoolSpace listing
A8: Stadium additional hours | B8: 2 | C8: 200 | D8: =B8*C8 -> 400 | E8: =D8*'1. Cover & Assumptions'!$B$18 -> 1200 | F8: Assumes 6 total hrs (warmup, game, post)
A9: Video board use (flat fee) | B9: 1 | C9: 1000 | D9: =B9*C9 -> 1000 | E9: =D9*'1. Cover & Assumptions'!$B$18 -> 3000 | F9: $1,000 flat per event
A10: Field supervisor | B10: 6 | C10: 25 | D10: =B10*C10 -> 150 | E10: =D10*'1. Cover & Assumptions'!$B$18 -> 450 | F10: $25/hr, 3-hr min, 1 person, 6 hrs
A11: Custodian (2 staff) | B11: 12 | C11: 25 | D11: =B11*C11 -> 300 | E11: =D11*'1. Cover & Assumptions'!$B$18 -> 900 | F11: 2 custodians x 6 hrs each
A12: Security officers (8 officers) | B12: 48 | C12: 30 | D12: =B12*C12 -> 1440 | E12: =D12*'1. Cover & Assumptions'!$B$18 -> 4320 | F12: 8 officers x 6 hrs for 1,875+ attendance
A13: Concession buyout (if Tyler ISD declines) | B13: 1 | C13: 250 | D13: =B13*C13 -> 250 | E13: =D13*'1. Cover & Assumptions'!$B$18 -> 750 | F13: $250/day - assumes worst case
A14: Field paint, chalk, game-day consumables | B14: 1 | C14: 350 | D14: =B14*C14 -> 350 | E14: =D14*'1. Cover & Assumptions'!$B$18 -> 1050 | F14: Game prep consumables
A15: EMT / on-site medical | B15: 6 | C15: 60 | D15: =B15*C15 -> 360 | E15: =D15*'1. Cover & Assumptions'!$B$18 -> 1080 | F15: $60/hr ambulance standby
A16: Scoreboard / clock operator | B16: 6 | C16: 35 | D16: =B16*C16 -> 210 | E16: =D16*'1. Cover & Assumptions'!$B$18 -> 630 | F16: Game-day operator
A17: PA announcer | B17: 4 | C17: 150 | D17: =B17*C17 -> 600 | E17: =D17*'1. Cover & Assumptions'!$B$18 -> 1800 | F17: Flat-rate per game ~$600
A18: TOTAL PER GAME | D18: =SUM(D7:D17) -> 7060 | E18: =SUM(E7:E17) -> 21180
A20: REQUIRED EMPLOYEES (STADIUM-SIDE & GAME-DAY)
A21: Role | B21: Headcount | C21: Source
A22: Field supervisor (Tyler ISD) | B22: 1 | C22: Stadium req.
A23: Custodians (Tyler ISD) | B23: 2 | C23: Stadium req.
A24: Security officers (Tyler ISD) | B24: 8 | C24: Capacity-based, ~1 per 235 attendees
A25: EMT / medical standby | B25: 2 | C25: Industry standard
A26: Scoreboard / clock operator | B26: 1 | C26: Stadium req.
A27: PA announcer | B27: 1 | C27: Per game
A28: Ticket takers / ushers | B28: 6 | C28: Game-day workers (per breakeven)
A29: Concession workers (if buyout) | B29: 12 | C29: Tyler ISD usually runs
A30: Equipment manager | B30: 1 | C30: Per breakeven workbook
A31: Athletic trainers | B31: 2 | C31: Per breakeven workbook
A32: Officials (game refs) | B32: 6 | C32: Per breakeven workbook
A33: Coaching staff (HC + 6 assistants) | B33: 7 | C33: Per breakeven workbook
A34: Front office (GM, marketing, ops) | B34: 3 | C34: $24K front office line in breakeven

Sheet 4. Year 1 Proforma
A1: YEAR 1 PROFORMA INCOME STATEMENT - 2026 SEASON
A3: Built off existing TylerCoFL Compass breakeven model + Rose Stadium + franchise/legal + missing-cost additions
A5: REVENUE
A6: Line Item | B6: Qty/Seats | C6: $/Unit | D6: # Games | E6: Total | F6: Notes
A7: Premium tickets (between 40-yd lines) | B7: 200 | C7: 35 | D7: 3 | E7: =B7*C7*D7 -> 21000 | F7: Per breakeven workbook
A8: Reserved tickets (between 30-40 yd lines) | B8: 400 | C8: 25 | D8: 3 | E8: =B8*C8*D8 -> 30000 | F8: Per breakeven workbook
A9: General admission | B9: 1000 | C9: 15 | D9: 3 | E9: =B9*C9*D9 -> 45000 | F9: Per breakeven workbook
A10: Group sales | B10: 275 | C10: 10 | D10: 3 | E10: =B10*C10*D10 -> 8250 | F10: Per breakeven workbook
A11: Concessions (50% of attendees @ $10) | B11: =SUM(B7:B10)*0.5 -> 937.5 | C11: 10 | D11: 3 | E11: =B11*C11*D11 -> 28125 | F11: Per breakeven workbook
A12: Beer garden (10% of attendees @ $25) | B12: =SUM(B7:B10)*0.1 -> 187.5 | C12: 25 | D12: 3 | E12: =B12*C12*D12 -> 14062.5 | F12: Per breakeven workbook
A13: Sponsorships (net 20% commission) | B13: 1 | C13: 131600 | D13: 1 | E13: =B13*C13*D13 -> 131600 | F13: Per breakeven workbook
A14: Food truck rental | B14: 10 | C14: 250 | D14: 3 | E14: =B14*C14*D14 -> 7500 | F14: Per breakeven workbook
A15: Merchandise (20% of attendees @ $20) | B15: =SUM(B7:B10)*0.2 -> 375 | C15: 20 | D15: 3 | E15: =B15*C15*D15 -> 22500 | F15: Per breakeven workbook
A16: 50/50 raffle | B16: 1 | C16: 2000 | D16: 3 | E16: =B16*C16*D16 -> 6000 | F16: Per breakeven workbook
A17: WeFunder community equity campaign | B17: 100 | C17: 1000 | D17: 1 | E17: =B17*C17*D17 -> 100000 | F17: One-time fundraise (NOT recurring)
A18: TOTAL REVENUE | E18: =SUM(E7:E17) -> 414037.5
A20: OPERATIONAL EXPENSES (Player & Equipment)
A21: Line Item | B21: Units | C21: Cost | D21: Quantity | E21: Total | F21: Notes
A22: Front office (salaries, benefits, overhead) | B22: 1 | C22: 24000 | D22: 1 | E22: =B22*C22*D22 -> 24000 | F22: Per breakeven workbook
A23: Game uniforms (jersey & pants, 2 sets) | B23: 2 | C23: 175 | D23: 50 | E23: =B23*C23*D23 -> 17500 | F23: Per breakeven workbook
A24: Practice uniforms (jersey & shorts) | B24: 1 | C24: 80 | D24: 50 | E24: =B24*C24*D24 -> 4000 | F24: Per breakeven workbook
A25: Helmets | B25: 1 | C25: 500 | D25: 50 | E25: =B25*C25*D25 -> 25000 | F25: Per breakeven workbook
A26: Shoulder pads | B26: 1 | C26: 300 | D26: 50 | E26: =B26*C26*D26 -> 15000 | F26: Per breakeven workbook
A27: Player / coach apparel | B27: 1 | C27: 70 | D27: 50 | E27: =B27*C27*D27 -> 3500 | F27: Per breakeven workbook
A28: CoFL footballs (practice & game) | B28: 1 | C28: 175 | D28: 16 | E28: =B28*C28*D28 -> 2800 | F28: Per breakeven workbook
A29: Athletic trainers (stipend per week) | B29: 8 | C29: 500 | D29: 2 | E29: =B29*C29*D29 -> 8000 | F29: Per breakeven workbook
A30: Total Operational Expenses | E30: =SUM(E22:E29) -> 99800
A32: GAME DAY EXPENSES
A33: Line Item | B33: Games/Days | C33: Per Game | D33: People | E33: Total | F33: Notes
A34: Rose Stadium rental (linked from Sheet 3) | E34: ='3. Rose Stadium Detail'!$E$18 -> 21180 | F34: REPLACES the $3K placeholder; full per-game build on Sheet 3
A35: Practice facility fee | B35: 21 | C35: 100 | D35: 1 | E35: =B35*C35*D35 -> 2100 | F35: Per breakeven workbook
A36: Coaches stipend (assistant coaches) | B36: 6 | C36: 1000 | D36: 7 | E36: =B36*C36*D36 -> 42000 | F36: Per breakeven workbook
A37: Head coach stipend | B37: 1 | C37: 60000 | D37: 1 | E37: =B37*C37*D37 -> 60000 | F37: Per breakeven workbook
A38: Equipment manager | B38: 6 | C38: 500 | D38: 1 | E38: =B38*C38*D38 -> 3000 | F38: Per breakeven workbook
A39: Officials (refs) | B39: 3 | C39: 125 | D39: 6 | E39: =B39*C39*D39 -> 2250 | F39: Per breakeven workbook
A40: Player housing (dbl occupancy) | B40: 43 | C40: 54 | D40: 20 | E40: =B40*C40*D40 -> 46440 | F40: Per breakeven workbook
A41: Player pay | B41: 6 | C41: 400 | D41: 38 | E41: =B41*C41*D41 -> 91200 | F41: Per breakeven workbook
A42: Quarterback pay | B42: 6 | C42: 750 | D42: 2 | E42: =B42*C42*D42 -> 9000 | F42: Per breakeven workbook
A43: Game day workers (additional, not in stadium) | B43: 3 | C43: 120 | D43: 30 | E43: =B43*C43*D43 -> 10800 | F43: Per breakeven workbook
A44: Total Game Day Expenses | E44: =SUM(E34:E43) -> 287970
...

Sheet 5. 5-Year Forecast
A1: 5-YEAR PROFORMA FORECAST (2026-2030) | 10% annual revenue growth
A3: REVENUE - 10% annual growth (per Manny)
A4: Line Item | B4: Year 1 | C4: Year 2 | D4: Year 3 | E4: Year 4 | F4: Year 5
A5: Recurring revenue (ticket+conc+sponsor+merch+raffle+food trucks) | B5: ='4. Year 1 Proforma'!$E$18-'4. Year 1 Proforma'!$E$17 -> 314037.5 | C5: =B5*(1+'1. Cover & Assumptions'!$B$16) -> 345441.25 | D5: =C5*(1+'1. Cover & Assumptions'!$B$16) -> 379985.38 | E5: =D5*(1+'1. Cover & Assumptions'!$B$16) -> 417983.91 | F5: =E5*(1+'1. Cover & Assumptions'!$B$16) -> 459782.3
A6: WeFunder / Equity raise (one-time) | B6: ='4. Year 1 Proforma'!$E$17 -> 100000 | C6: 0 | D6: 0 | E6: 0 | F6: 0
A7: TOTAL REVENUE | B7: =SUM(B5:B6) -> 414037.5 | C7: =SUM(C5:C6) -> 345441.25 | D7: =SUM(D5:D6) -> 379985.38 | E7: =SUM(E5:E6) -> 417983.91 | F7: =SUM(F5:F6) -> 459782.3
A9: EXPENSES - inflated at general inflation rate
A10: Line Item | B10: Year 1 | C10: Year 2 | D10: Year 3 | E10: Year 4 | F10: Year 5
A11: Operational Expenses (player & equipment) | B11: ='4. Year 1 Proforma'!$E$30 -> 99800 | C11: =B11*(1+'1. Cover & Assumptions'!$B$17) -> 103792 | D11: =C11*(1+'1. Cover & Assumptions'!$B$17) -> 107943.68 | E11: =D11*(1+'1. Cover & Assumptions'!$B$17) -> 112261.43 | F11: =E11*(1+'1. Cover & Assumptions'!$B$17) -> 116751.88
A12: Game Day Expenses (incl Rose Stadium) | B12: ='4. Year 1 Proforma'!$E$44 -> 287970 | C12: =B12*(1+'1. Cover & Assumptions'!$B$17) -> 299488.8 | D12: =C12*(1+'1. Cover & Assumptions'!$B$17) -> 311468.35 | E12: =D12*(1+'1. Cover & Assumptions'!$B$17) -> 323927.09 | F12: =E12*(1+'1. Cover & Assumptions'!$B$17) -> 336884.17
A13: Away Game Logistics | B13: ='4. Year 1 Proforma'!$E$51 -> 31500 | C13: =B13*(1+'1. Cover & Assumptions'!$B$17) -> 32760 | D13: =C13*(1+'1. Cover & Assumptions'!$B$17) -> 34070.4 | E13: =D13*(1+'1. Cover & Assumptions'!$B$17) -> 35433.216 | F13: =E13*(1+'1. Cover & Assumptions'!$B$17) -> 36850.545
A14: League / Franchise / Corp Overhead | B14: ='4. Year 1 Proforma'!$E$83 -> 282381.62 | C14: =(B14-'4. Year 1 Proforma'!$E$56)*(1+'1. Cover & Assumptions'!$B$17) -> 285876.89 | D14: =C14*(1+'1. Cover & Assumptions'!$B$17) -> 297311.97 | E14: =D14*(1+'1. Cover & Assumptions'!$B$17) -> 309204.44 | F14: =E14*(1+'1. Cover & Assumptions'!$B$17) -> 321572.62
A15: TOTAL EXPENSES | B15: =SUM(B11:B14) -> 701651.62 | C15: =SUM(C11:C14) -> 721917.69 | D15: =SUM(D11:D14) -> 750794.4 | E15: =SUM(E11:E14) -> 780826.17 | F15: =SUM(F11:F14) -> 812059.22
A17: NET INCOME (LOSS) | B17: =B7-B15 -> -287614.12 | C17: =C7-C15 -> -376476.44 | D17: =D7-D15 -> -370809.02 | E17: =E7-E15 -> -362842.26 | F17: =F7-F15 -> -352276.92
A18: Net margin % | B18: =B17/B7 -> -0.69465719 | C18: =C17/C7 -> -1.0898422 | D18: =D17/D7 -> -0.97585077 | E18: =E17/E7 -> -0.8680771 | F18: =F17/F7 -> -0.76618198
A19: Cumulative Net Income | B19: =B17 -> -287614.12 | C19: =B19+C17 -> -664090.56 | D19: =C19+D17 -> -1034899.6 | E19: =D19+E17 -> -1397741.8 | F19: =E19+F17 -> -1750018.8
A21: Memo: Rose Stadium cost (per season) growing 4%
A22: Rose Stadium / season | B22: ='3. Rose Stadium Detail'!$E$18 -> 21180 | C22: =B22*(1+'1. Cover & Assumptions'!$B$17) -> 22027.2 | D22: =C22*(1+'1. Cover & Assumptions'!$B$17) -> 22908.288 | E22: =D22*(1+'1. Cover & Assumptions'!$B$17) -> 23824.62 | F22: =E22*(1+'1. Cover & Assumptions'!$B$17) -> 24777.604
A23: Annual franchise fee | B23: ='1. Cover & Assumptions'!$B$22 -> 50000 | C23: ='1. Cover & Assumptions'!$B$22 -> 50000 | D23: ='1. Cover & Assumptions'!$B$22 -> 50000 | E23: ='1. Cover & Assumptions'!$B$22 -> 50000 | F23: ='1. Cover & Assumptions'!$B$22 -> 50000

Sheet 6. 10-Year Forecast
A1: 10-YEAR PROFORMA FORECAST (2026-2035) | 10% annual revenue growth
A3: REVENUE - 10% annual growth (per Manny)
A4: Line Item | B4: Year 1 | C4: Year 2 | D4: Year 3 | E4: Year 4 | F4: Year 5 | G4: Year 6 | H4: Year 7 | I4: Year 8 | J4: Year 9 | K4: Year 10
A5: Recurring revenue (ticket+conc+sponsor+merch+raffle+food trucks) | B5: ='4. Year 1 Proforma'!$E$18 -> 414037.5 | C5: =B5*(1+'1. Cover & Assumptions'!$B$16) -> 455441.25 | D5: =C5*(1+'1. Cover & Assumptions'!$B$16) -> 500985.38 | E5: =D5*(1+'1. Cover & Assumptions'!$B$16) -> 551083.91 | F5: =E5*(1+'1. Cover & Assumptions'!$B$16) -> 606192.3 | G5: =F5*(1+'1. Cover & Assumptions'!$B$16) -> 666811.53 | H5: =G5*(1+'1. Cover & Assumptions'!$B$16) -> 733492.69 | I5: =H5*(1+'1. Cover & Assumptions'!$B$16) -> 806841.96 | J5: =I5*(1+'1. Cover & Assumptions'!$B$16) -> 887526.15 | K5: =J5*(1+'1. Cover & Assumptions'!$B$16) -> 976278.77
A6: WeFunder / Equity raise (one-time) | C6: 0 | D6: 0 | E6: 0 | F6: 0 | G6: 0 | H6: 0 | I6: 0 | J6: 0 | K6: 0
A7: TOTAL REVENUE | B7: =SUM(B5:B6) -> 414037.5 | C7: =SUM(C5:C6) -> 455441.25 | D7: =SUM(D5:D6) -> 500985.38 | E7: =SUM(E5:E6) -> 551083.91 | F7: =SUM(F5:F6) -> 606192.3 | G7: =SUM(G5:G6) -> 666811.53 | H7: =SUM(H5:H6) -> 733492.69 | I7: =SUM(I5:I6) -> 806841.96 | ... K7: =SUM(K5:K6) -> 976278.77
A9: EXPENSES - inflated at general inflation rate
A10: Line Item | B10: Year 1 | C10: Year 2 | D10: Year 3 | E10: Year 4 | F10: Year 5 | G10: Year 6 | H10: Year 7 | I10: Year 8 | J10: Year 9 | K10: Year 10
A11: Operational Expenses (player & equipment) | B11: ='4. Year 1 Proforma'!$E$30 -> 99800 | C11: =B11*(1+'1. Cover & Assumptions'!$B$17) -> 103792 | D11: =C11*(1+'1. Cover & Assumptions'!$B$17) -> 107943.68 | E11: =D11*(1+'1. Cover & Assumptions'!$B$17) -> 112261.43 | F11: =E11*(1+'1. Cover & Assumptions'!$B$17) -> 116751.88 | G11: =F11*(1+'1. Cover & Assumptions'!$B$17) -> 121421.96 | H11: =G11*(1+'1. Cover & Assumptions'!$B$17) -> 126278.84 | I11: =H11*(1+'1. Cover & Assumptions'!$B$17) -> 131329.99 | J11: =I11*(1+'1. Cover & Assumptions'!$B$17) -> 136583.19 | K11: =J11*(1+'1. Cover & Assumptions'!$B$17) -> 142046.52
A12: Game Day Expenses (incl Rose Stadium) | B12: ='4. Year 1 Proforma'!$E$44 -> 287970 | C12: =B12*(1+'1. Cover & Assumptions'!$B$17) -> 299488.8 | D12: =C12*(1+'1. Cover & Assumptions'!$B$17) -> 311468.35 | E12: =D12*(1+'1. Cover & Assumptions'!$B$17) -> 323927.09 | F12: =E12*(1+'1. Cover & Assumptions'!$B$17) -> 336884.17 | G12: =F12*(1+'1. Cover & Assumptions'!$B$17) -> 350359.54 | H12: =G12*(1+'1. Cover & Assumptions'!$B$17) -> 364373.92 | I12: =H12*(1+'1. Cover & Assumptions'!$B$17) -> 378948.87 | J12: =I12*(1+'1. Cover & Assumptions'!$B$17) -> 394106.83 | K12: =J12*(1+'1. Cover & Assumptions'!$B$17) -> 409871.1
A13: Away Game Logistics | B13: ='4. Year 1 Proforma'!$E$51 -> 31500 | C13: =B13*(1+'1. Cover & Assumptions'!$B$17) -> 32760 | D13: =C13*(1+'1. Cover & Assumptions'!$B$17) -> 34070.4 | E13: =D13*(1+'1. Cover & Assumptions'!$B$17) -> 35433.216 | F13: =E13*(1+'1. Cover & Assumptions'!$B$17) -> 36850.545 | G13: =F13*(1+'1. Cover & Assumptions'!$B$17) -> 38324.566 | H13: =G13*(1+'1. Cover & Assumptions'!$B$17) -> 39857.549 | I13: =H13*(1+'1. Cover & Assumptions'!$B$17) -> 41451.851 | J13: =I13*(1+'1. Cover & Assumptions'!$B$17) -> 43109.925 | K13: =J13*(1+'1. Cover & Assumptions'!$B$17) -> 44834.322
A14: League / Franchise / Corp Overhead | B14: ='4. Year 1 Proforma'!$E$83 -> 282381.62 | C14: =B14*(1+'1. Cover & Assumptions'!$B$17) -> 293676.89 | D14: =C14*(1+'1. Cover & Assumptions'!$B$17) -> 305423.97 | E14: =D14*(1+'1. Cover & Assumptions'!$B$17) -> 317640.92 | F14: =E14*(1+'1. Cover & Assumptions'!$B$17) -> 330346.56 | G14: =F14*(1+'1. Cover & Assumptions'!$B$17) -> 343560.42 | H14: =G14*(1+'1. Cover & Assumptions'!$B$17) -> 357302.84 | I14: =H14*(1+'1. Cover & Assumptions'!$B$17) -> 371594.95 | J14: =I14*(1+'1. Cover & Assumptions'!$B$17) -> 386458.75 | K14: =J14*(1+'1. Cover & Assumptions'!$B$17) -> 401917.1
A15: TOTAL EXPENSES | B15: =SUM(B11:B14) -> 701651.62 | C15: =SUM(C11:C14) -> 729717.69 | D15: =SUM(D11:D14) -> 758906.4 | E15: =SUM(E11:E14) -> 789262.65 | F15: =SUM(F11:F14) -> 820833.16 | G15: =SUM(G11:G14) -> 853666.49 | H15: =SUM(H11:H14) -> 887813.15 | I15: =SUM(I11:I14) -> 923325.67 | ... K15: =SUM(K11:K14) -> 998669.05
A17: NET INCOME (LOSS) | B17: =B7-B15 -> -287614.12 | C17: =C7-C15 -> -274276.44 | D17: =D7-D15 -> -257921.02 | E17: =E7-E15 -> -238178.74 | F17: =F7-F15 -> -214640.86 | G17: =G7-G15 -> -186854.95 | H17: =H7-H15 -> -154320.46 | I17: =I7-I15 -> -116483.71 | ... K17: =K7-K15 -> -22390.279
A18: Net margin % | B18: =B17/B7 -> -0.69465719 | C18: =C17/C7 -> -0.60222134 | D18: =D17/D7 -> -0.51482745 | E18: =E17/E7 -> -0.4322005 | F18: =F17/F7 -> -0.35408047 | G18: =G17/G7 -> -0.28022154 | H18: =H17/H7 -> -0.21039127 | I18: =I17/I7 -> -0.14436993 | ... K18: =K17/K7 -> -0.022934309
A19: Cumulative Net Income | B19: =B17 -> -287614.12 | C19: =B19+C17 -> -561890.56 | D19: =C19+D17 -> -819811.59 | E19: =D19+E17 -> -1057990.3 | F19: =E19+F17 -> -1272631.2 | G19: =F19+G17 -> -1459486.1 | H19: =G19+H17 -> -1613806.6 | I19: =H19+I17 -> -1730290.3 | J19: =I19+J17 -> -1803022.9 | K19: =J19+K17 -> -1825413.1
A21: Memo: Rose Stadium cost (per season) growing 4%
A22: Rose Stadium / season | B22: ='3. Rose Stadium Detail'!$E$18 -> 21180 | C22: =B22*(1+'1. Cover & Assumptions'!$B$17) -> 22027.2 | D22: =C22*(1+'1. Cover & Assumptions'!$B$17) -> 22908.288 | E22: =D22*(1+'1. Cover & Assumptions'!$B$17) -> 23824.62 | F22: =E22*(1+'1. Cover & Assumptions'!$B$17) -> 24777.604 | G22: =F22*(1+'1. Cover & Assumptions'!$B$17) -> 25768.708 | H22: =G22*(1+'1. Cover & Assumptions'!$B$17) -> 26799.457 | I22: =H22*(1+'1. Cover & Assumptions'!$B$17) -> 27871.435 | J22: =I22*(1+'1. Cover & Assumptions'!$B$17) -> 28986.292 | K22: =J22*(1+'1. Cover & Assumptions'!$B$17) -> 30145.744
A23: Annual franchise fee | B23: ='1. Cover & Assumptions'!$B$22 -> 50000 | C23: ='1. Cover & Assumptions'!$B$22 -> 50000 | D23: ='1. Cover & Assumptions'!$B$22 -> 50000 | E23: ='1. Cover & Assumptions'!$B$22 -> 50000 | F23: ='1. Cover & Assumptions'!$B$22 -> 50000 | G23: ='1. Cover & Assumptions'!$B$22 -> 50000 | H23: ='1. Cover & Assumptions'!$B$22 -> 50000 | I23: ='1. Cover & Assumptions'!$B$22 -> 50000 | ... K23: ='1. Cover & Assumptions'!$B$22 -> 50000

Sheet Nates capital budgeting
A1: 10-YEAR PROFORMA FORECAST (2026-2035) | 10% annual revenue growth
A3: REVENUE - 10% annual growth (per Manny)
A4: Line Item | B4: Year 1 | C4: Year 2 | D4: Year 3 | E4: Year 4 | F4: Year 5 | G4: Year 6 | H4: Year 7 | I4: Year 8 | J4: Year 9 | K4: Year 10
A5: Recurring revenue (ticket+conc+sponsor+merch+raffle+food trucks) | B5: ='4. Year 1 Proforma'!$E$18 -> 414037.5 | C5: =B5*(1+'1. Cover & Assumptions'!$B$16) -> 455441.25 | D5: =C5*(1+'1. Cover & Assumptions'!$B$16) -> 500985.38 | E5: =D5*(1+'1. Cover & Assumptions'!$B$16) -> 551083.91 | F5: =E5*(1+'1. Cover & Assumptions'!$B$16) -> 606192.3 | G5: =F5*(1+'1. Cover & Assumptions'!$B$16) -> 666811.53 | H5: =G5*(1+'1. Cover & Assumptions'!$B$16) -> 733492.69 | I5: =H5*(1+'1. Cover & Assumptions'!$B$16) -> 806841.96 | J5: =I5*(1+'1. Cover & Assumptions'!$B$16) -> 887526.15 | K5: =J5*(1+'1. Cover & Assumptions'!$B$16) -> 976278.77
A6: WeFunder / Equity raise (one-time) | C6: 0 | D6: 0 | E6: 0 | F6: 0 | G6: 0 | H6: 0 | I6: 0 | J6: 0 | K6: 0
A7: TOTAL REVENUE | B7: =SUM(B5:B6) -> 414037.5 | C7: =SUM(C5:C6) -> 455441.25 | D7: =SUM(D5:D6) -> 500985.38 | E7: =SUM(E5:E6) -> 551083.91 | F7: =SUM(F5:F6) -> 606192.3 | G7: =SUM(G5:G6) -> 666811.53 | H7: =SUM(H5:H6) -> 733492.69 | I7: =SUM(I5:I6) -> 806841.96 | ... K7: =SUM(K5:K6) -> 976278.77
A9: EXPENSES - inflated at general inflation rate
A10: Line Item | B10: Year 1 | C10: Year 2 | D10: Year 3 | E10: Year 4 | F10: Year 5 | G10: Year 6 | H10: Year 7 | I10: Year 8 | J10: Year 9 | K10: Year 10
A11: Operational Expenses (player & equipment) | B11: ='4. Year 1 Proforma'!$E$30 -> 99800 | C11: =B11*(1+'1. Cover & Assumptions'!$B$17) -> 103792 | D11: =C11*(1+'1. Cover & Assumptions'!$B$17) -> 107943.68 | E11: =D11*(1+'1. Cover & Assumptions'!$B$17) -> 112261.43 | F11: =E11*(1+'1. Cover & Assumptions'!$B$17) -> 116751.88 | G11: =F11*(1+'1. Cover & Assumptions'!$B$17) -> 121421.96 | H11: =G11*(1+'1. Cover & Assumptions'!$B$17) -> 126278.84 | I11: =H11*(1+'1. Cover & Assumptions'!$B$17) -> 131329.99 | J11: =I11*(1+'1. Cover & Assumptions'!$B$17) -> 136583.19 | K11: =J11*(1+'1. Cover & Assumptions'!$B$17) -> 142046.52 | M11: =B11*1.04 -> 103792 | N11: =C11*1.04 -> 107943.68 | O11: =D11*1.04 -> 112261.43 | P11: =E11*1.04 -> 116751.88
A12: Game Day Expenses (incl Rose Stadium) | B12: ='4. Year 1 Proforma'!$E$44 -> 287970 | C12: =B12*(1+'1. Cover & Assumptions'!$B$17) -> 299488.8 | D12: =C12*(1+'1. Cover & Assumptions'!$B$17) -> 311468.35 | E12: =D12*(1+'1. Cover & Assumptions'!$B$17) -> 323927.09 | F12: =E12*(1+'1. Cover & Assumptions'!$B$17) -> 336884.17 | G12: =F12*(1+'1. Cover & Assumptions'!$B$17) -> 350359.54 | H12: =G12*(1+'1. Cover & Assumptions'!$B$17) -> 364373.92 | I12: =H12*(1+'1. Cover & Assumptions'!$B$17) -> 378948.87 | J12: =I12*(1+'1. Cover & Assumptions'!$B$17) -> 394106.83 | K12: =J12*(1+'1. Cover & Assumptions'!$B$17) -> 409871.1 | M12: =B12*1.04 -> 299488.8 | N12: =C12*1.04 -> 311468.35 | O12: =D12*1.04 -> 323927.09 | P12: =E12*1.04 -> 336884.17
A13: Away Game Logistics | B13: ='4. Year 1 Proforma'!$E$51 -> 31500 | C13: =B13*(1+'1. Cover & Assumptions'!$B$17) -> 32760 | D13: =C13*(1+'1. Cover & Assumptions'!$B$17) -> 34070.4 | E13: =D13*(1+'1. Cover & Assumptions'!$B$17) -> 35433.216 | F13: =E13*(1+'1. Cover & Assumptions'!$B$17) -> 36850.545 | G13: =F13*(1+'1. Cover & Assumptions'!$B$17) -> 38324.566 | H13: =G13*(1+'1. Cover & Assumptions'!$B$17) -> 39857.549 | I13: =H13*(1+'1. Cover & Assumptions'!$B$17) -> 41451.851 | J13: =I13*(1+'1. Cover & Assumptions'!$B$17) -> 43109.925 | K13: =J13*(1+'1. Cover & Assumptions'!$B$17) -> 44834.322 | M13: =B13*1.04 -> 32760 | N13: =C13*1.04 -> 34070.4 | O13: =D13*1.04 -> 35433.216 | P13: =E13*1.04 -> 36850.545
A14: League / Franchise / Corp Overhead | B14: ='4. Year 1 Proforma'!$E$83 -> 282381.62 | C14: =B14*(1+'1. Cover & Assumptions'!$B$17) -> 293676.89 | D14: =C14*(1+'1. Cover & Assumptions'!$B$17) -> 305423.97 | E14: =D14*(1+'1. Cover & Assumptions'!$B$17) -> 317640.92 | F14: =E14*(1+'1. Cover & Assumptions'!$B$17) -> 330346.56 | G14: =F14*(1+'1. Cover & Assumptions'!$B$17) -> 343560.42 | H14: =G14*(1+'1. Cover & Assumptions'!$B$17) -> 357302.84 | I14: =H14*(1+'1. Cover & Assumptions'!$B$17) -> 371594.95 | J14: =I14*(1+'1. Cover & Assumptions'!$B$17) -> 386458.75 | K14: =J14*(1+'1. Cover & Assumptions'!$B$17) -> 401917.1 | M14: =B14*1.04 -> 293676.89 | N14: =C14*1.04 -> 305423.97 | O14: =D14*1.04 -> 317640.92 | P14: =E14*1.04 -> 330346.56
A15: TOTAL EXPENSES | B15: =SUM(B11:B14) -> 701651.62 | C15: =SUM(C11:C14) -> 729717.69 | D15: =SUM(D11:D14) -> 758906.4 | E15: =SUM(E11:E14) -> 789262.65 | F15: =SUM(F11:F14) -> 820833.16 | G15: =SUM(G11:G14) -> 853666.49 | H15: =SUM(H11:H14) -> 887813.15 | I15: =SUM(I11:I14) -> 923325.67 | ... K15: =SUM(K11:K14) -> 998669.05 | M15: =B15*1.04 -> 729717.69 | N15: =C15*1.04 -> 758906.4 | O15: =D15*1.04 -> 789262.65 | P15: =E15*1.04 -> 820833.16
A17: NET INCOME (LOSS) | B17: =B7-B15 -> -287614.12 | C17: =C7-C15 -> -274276.44 | D17: =D7-D15 -> -257921.02 | E17: =E7-E15 -> -238178.74 | F17: =F7-F15 -> -214640.86 | G17: =G7-G15 -> -186854.95 | H17: =H7-H15 -> -154320.46 | I17: =I7-I15 -> -116483.71 | ... K17: =K7-K15 -> -22390.279
A18: Net margin % | B18: =B17/B7 -> -0.69465719 | C18: =C17/C7 -> -0.60222134 | D18: =D17/D7 -> -0.51482745 | E18: =E17/E7 -> -0.4322005 | F18: =F17/F7 -> -0.35408047 | G18: =G17/G7 -> -0.28022154 | H18: =H17/H7 -> -0.21039127 | I18: =I17/I7 -> -0.14436993 | ... K18: =K17/K7 -> -0.022934309
A19: Cumulative Net Income | B19: =B17 -> -287614.12 | C19: =B19+C17 -> -561890.56 | D19: =C19+D17 -> -819811.59 | E19: =D19+E17 -> -1057990.3 | F19: =E19+F17 -> -1272631.2 | G19: =F19+G17 -> -1459486.1 | H19: =G19+H17 -> -1613806.6 | I19: =H19+I17 -> -1730290.3 | J19: =I19+J17 -> -1803022.9 | K19: =J19+K17 -> -1825413.1
A21: Memo: Rose Stadium cost (per season) growing 4%
A22: Rose Stadium / season | B22: ='3. Rose Stadium Detail'!$E$18 -> 21180 | C22: =B22*(1+'1. Cover & Assumptions'!$B$17) -> 22027.2 | D22: =C22*(1+'1. Cover & Assumptions'!$B$17) -> 22908.288 | E22: =D22*(1+'1. Cover & Assumptions'!$B$17) -> 23824.62 | F22: =E22*(1+'1. Cover & Assumptions'!$B$17) -> 24777.604 | G22: =F22*(1+'1. Cover & Assumptions'!$B$17) -> 25768.708 | H22: =G22*(1+'1. Cover & Assumptions'!$B$17) -> 26799.457 | I22: =H22*(1+'1. Cover & Assumptions'!$B$17) -> 27871.435 | J22: =I22*(1+'1. Cover & Assumptions'!$B$17) -> 28986.292 | K22: =J22*(1+'1. Cover & Assumptions'!$B$17) -> 30145.744
A23: Annual franchise fee | B23: ='1. Cover & Assumptions'!$B$22 -> 50000 | C23: ='1. Cover & Assumptions'!$B$22 -> 50000 | D23: ='1. Cover & Assumptions'!$B$22 -> 50000 | E23: ='1. Cover & Assumptions'!$B$22 -> 50000 | F23: ='1. Cover & Assumptions'!$B$22 -> 50000 | G23: ='1. Cover & Assumptions'!$B$22 -> 50000 | H23: ='1. Cover & Assumptions'!$B$22 -> 50000 | I23: ='1. Cover & Assumptions'!$B$22 -> 50000 | ... K23: ='1. Cover & Assumptions'!$B$22 -> 50000
G25: Payback | H25: 0.0935 | I25: Discounted Payback
A26: Period | B26: Cost to buy | C26: Sponsorships | D26: Revenues | E26: Expenses | F26: Net CF | G26: To Recoup | H26: PV | I26: PV to Recoup
A27: 0 | B27: =-'2. Initial Investment'!D23 -> -416000 | C27: ='2. Initial Investment'!B32 -> 580000 | F27: =SUM(B27:E27) -> 164000 | G27: =F27 -> 164000 | H27: =F27/(1+$H$25)^A27 -> 164000 | I27: =H27 -> 164000
A28: 1 | D28: =B7 -> 414037.5 | E28: =-B15 -> -701651.62 | F28: =SUM(B28:E28) -> -287614.12 | G28: =G27+F28 -> -123614.12 | H28: =F28/(1+$H$25)^A28 -> -263021.6 | I28: =I27+H28 -> -99021.605
A29: 2 | D29: =($D$37-$D$28)/9+D28 -> 506366.67 | E29: =-C15 -> -729717.69 | F29: =SUM(B29:E29) -> -223351.02 | G29: =G28+F29 -> -346965.15 | H29: =F29/(1+$H$25)^A29 -> -186788.6 | I29: =I28+H29 -> -285810.21
A30: 3 | D30: =($D$37-$D$28)/9+D29 -> 598695.83 | E30: =-D15 -> -758906.4 | F30: =SUM(B30:E30) -> -160210.56 | G30: =G29+F30 -> -507175.71 | H30: =F30/(1+$H$25)^A30 -> -122527.84 | I30: =I29+H30 -> -408338.05
A31: 4 | D31: =($D$37-$D$28)/9+D30 -> 691025 | E31: =-E15 -> -789262.65 | F31: =SUM(B31:E31) -> -98237.654 | G31: =G30+F31 -> -605413.37 | H31: =F31/(1+$H$25)^A31 -> -68707.292 | I31: =I30+H31 -> -477045.34
A32: 5 | D32: =($D$37-$D$28)/9+D31 -> 783354.17 | E32: =-F15 -> -820833.16 | F32: =SUM(B32:E32) -> -37478.993 | G32: =G31+F32 -> -642892.36 | H32: =F32/(1+$H$25)^A32 -> -23971.432 | I32: =I31+H32 -> -501016.77
A33: 6 | D33: =($D$37-$D$28)/9+D32 -> 875683.33 | E33: =-G15 -> -853666.49 | F33: =SUM(B33:E33) -> 22016.847 | G33: =G32+F33 -> -620875.51 | H33: =F33/(1+$H$25)^A33 -> 12877.822 | I33: =I32+H33 -> -488138.95
A34: 7 | D34: =($D$37-$D$28)/9+D33 -> 968012.5 | E34: =-H15 -> -887813.15 | F34: =SUM(B34:E34) -> 80199.355 | G34: =G33+F34 -> -540676.16 | H34: =F34/(1+$H$25)^A34 -> 42898.229 | I34: =I33+H34 -> -445240.72
A35: 8 | D35: =($D$37-$D$28)/9+D34 -> 1060341.7 | E35: =-I15 -> -923325.67 | F35: =SUM(B35:E35) -> 137016 | G35: =G34+F35 -> -403660.16 | H35: =F35/(1+$H$25)^A35 -> 67022.554 | I35: =I34+H35 -> -378218.17
A36: 9 | D36: =($D$37-$D$28)/9+D35 -> 1152670.8 | E36: =-J15 -> -960258.7 | F36: =SUM(B36:E36) -> 192412.14 | G36: =G35+F36 -> -211248.03 | H36: =F36/(1+$H$25)^A36 -> 86072.293 | I36: =I35+H36 -> -292145.88
A37: 10 | D37: 1245000 | E37: =-K15 -> -998669.05 | F37: =SUM(B37:E37) -> 246330.95 | G37: =G36+F37 -> 35082.927 | H37: =F37/(1+$H$25)^A37 -> 100769.97 | I37: =I36+H37 -> -191375.91 | J37: no breakeven point within 10 years for discounted payback
G39: NPV: | H39: =SUM(H27:H37) -> -191375.91
G40: NPV (check): | H40: =F27+NPV(H25,F28:F37) -> -191375.91
G41: IRR: | H41: =IRR(F27:F37) -> 0.0088508778
G42: MIRR: | H42: =MIRR(F27:F37,H25,H25) -> 0.05701328

Sheet Nates screenshots

Sheet 7. Sponsorship Plan
A1: SPONSORSHIP PLAN - WEFUNDER PROFILE + TIER STRUCTURE
A3: Anchor strategy: lead with CHRISTUS Health (already on stadium); fill tiers with regional brands.
A5: SPONSORSHIP TIERS
A6: Tier | B6: Annual $ each | C6: # Spots | D6: Total $ | E6: Cumulative | F6: Benefits
A7: Title / Naming Rights (CHRISTUS target) | B7: 75000 | C7: 1 | D7: =B7*C7 -> 75000 | E7: =D7 -> 75000 | F7: Stadium-aligned name presence; top logo placement; LED dominance; PA mentions; suite
A8: Platinum | B8: 25000 | C8: 4 | D8: =B8*C8 -> 100000 | E8: =E7+D8 -> 175000 | F8: Field signage; jersey patch; suite access; 50 tickets/game
A9: Gold | B9: 10000 | C9: 8 | D9: =B9*C9 -> 80000 | E9: =E8+D9 -> 255000 | F9: Endzone signage; PA mentions; 30 tickets/game
A10: Silver | B10: 5000 | C10: 15 | D10: =B10*C10 -> 75000 | E10: =E9+D10 -> 330000 | F10: Concourse signage; 20 tickets/game; web logo
A11: Bronze | B11: 2500 | C11: 25 | D11: =B11*C11 -> 62500 | E11: =E10+D11 -> 392500 | F11: Program ad; 10 tickets/game; web logo
A12: Local business / community | B12: 1000 | C12: 40 | D12: =B12*C12 -> 40000 | E12: =E11+D12 -> 432500 | F12: Web logo; 4 tickets/game
A13: GROSS SPONSORSHIP POTENTIAL | D13: =SUM(D7:D12) -> 432500
A14: Less: 20% sales commission | D14: =-D13*0.2 -> -86500
A15: NET TO TEAM (compare to $131,600 in breakeven workbook) | D15: =D13+D14 -> 346000
A18: WEFUNDER REG CF CAMPAIGN PROFILE
A19: Campaign type | B19: Regulation Crowdfunding (Reg CF) - up to $5M cap
A20: Working target | B20: $100,000 (per existing breakeven model)
A21: Stretch target | B21: $250,000
A22: Average check size | B22: $1,000
A23: Investor base | B23: Tyler/Smith County residents, alumni, sports fans, season-ticket prospects
A24: Investor perks | B24: Founders' jersey, naming on Founders Wall, season ticket discount, annual investor tailgate
A25: Anchor narrative | B25: First-ever East Texas pro football team; play at iconic Rose Stadium; CHRISTUS-anchored sponsor base
A26: Marketing mix | B26: Local PR, KETK / KLTV news, FB/IG geo-targeted ads, church & chamber outreach, alumni networks (UT Tyler, TJC, Lee/Tyler HS)
A27: Use of funds disclosure | B27: Equipment, marketing, working capital, league fees - itemized in Form C
A28: Compliance partner | B28: WeFunder (broker-dealer fees ~6.5% + escrow)
A31: TARGET ANCHOR & PRIORITY SPONSORS (East Texas)
A32: Sponsor | B32: Tier Target | C32: Rationale
A33: CHRISTUS Health | B33: Title / Naming | C33: Already title sponsor of Rose Stadium; natural alignment; healthcare leader
A34: UT Health East Texas | B34: Platinum | C34: Healthcare competitor; medical sponsor opportunity
A35: Brookshire Grocery Co. | B35: Platinum | C35: Headquartered in Tyler; strong community ties
A36: Southside Bank / Texas Bank & Trust | B36: Platinum | C36: Regional bank presence
A37: Tyler Toyota / Patterson Auto Group | B37: Gold | C37: Auto dealer category
A38: Mid-South Synergy / Oncor | B38: Gold | C38: Energy / utility category
A39: Bush's Chicken / Stanley's BBQ | B39: Silver | C39: Local QSR / iconic Tyler eats
A40: UT Tyler / Tyler Junior College | B40: Silver | C40: Higher-ed partnership / talent pipeline
A41: Local law firms | B41: Bronze | C41: Community presence packs
A42: Local realtors / chambers | B42: Local Business | C42: High-volume small ticket

Sheet 8. Market & Catchment
A1: MARKET ANALYSIS - SMITH COUNTY & EAST TEXAS DRAW AREA
A3: POPULATION OF DRAW AREA
A4: Geography | B4: Population | C4: Distance from Tyler | D4: % Capture target | E4: Attendance contribution
A5: Smith County (home) | B5: 245000 | C5: 0 mi | D5: 0.012 | E5: =B5*D5 -> 2940
A6: Tyler (city only) | B6: 108000 | C6: 0 mi | D6: 0.02 | E6: =B6*D6 -> 2160
A7: Gregg County (Longview) | B7: 125000 | C7: 35 mi | D7: 0.005 | E7: =B7*D7 -> 625
A8: Henderson County | B8: 85000 | C8: 30 mi | D8: 0.004 | E8: =B8*D8 -> 340
A9: Cherokee County | B9: 50000 | C9: 30 mi | D9: 0.004 | E9: =B9*D9 -> 200
A10: Van Zandt County | B10: 60000 | C10: 35 mi | D10: 0.003 | E10: =B10*D10 -> 180
A11: Rusk County | B11: 52000 | C11: 40 mi | D11: 0.003 | E11: =B11*D11 -> 156
A12: Wood County | B12: 46000 | C12: 30 mi | D12: 0.003 | E12: =B12*D12 -> 138
A13: Anderson County | B13: 58000 | C13: 35 mi | D13: 0.003 | E13: =B13*D13 -> 174
A14: Upshur County | B14: 41000 | C14: 40 mi | D14: 0.003 | E14: =B14*D14 -> 123
A15: TOTAL CATCHMENT (excl. Tyler row to avoid double-count) | B15: =SUM(B5:B14)-B6 -> 762000 | E15: =SUM(E5:E14)-E6 -> 4876
A17: Modeled attendance / game (per breakeven workbook) | B17: ='1. Cover & Assumptions'!$B$21 -> 1875
A18: Stadium max capacity | B18: ='1. Cover & Assumptions'!$B$20 -> 10566
A19: Year 1 capacity utilization | B19: ='1. Cover & Assumptions'!$B$21/'1. Cover & Assumptions'!$B$20 -> 0.17745599
A21: ATTENDANCE GROWTH PATH (10% YoY)
A22: Year | B22: Avg Attendance | C22: Capacity % | D22: Stadium fits target?
A23: Year 1 | B23: ='1. Cover & Assumptions'!$B$21 -> 1875 | C23: =B23/'1. Cover & Assumptions'!$B$20 -> 0.17745599 | D23: =IF(B23<'1. Cover & Assumptions'!$B$20,"Yes","NO") -> Yes
A24: Year 2 | B24: =B23*(1+'1. Cover & Assumptions'!$B$16) -> 2062.5 | C24: =B24/'1. Cover & Assumptions'!$B$20 -> 0.19520159 | D24: =IF(B24<'1. Cover & Assumptions'!$B$20,"Yes","NO") -> Yes
A25: Year 3 | B25: =B24*(1+'1. Cover & Assumptions'!$B$16) -> 2268.75 | C25: =B25/'1. Cover & Assumptions'!$B$20 -> 0.21472175 | D25: =IF(B25<'1. Cover & Assumptions'!$B$20,"Yes","NO") -> Yes
A26: Year 4 | B26: =B25*(1+'1. Cover & Assumptions'!$B$16) -> 2495.625 | C26: =B26/'1. Cover & Assumptions'!$B$20 -> 0.23619392 | D26: =IF(B26<'1. Cover & Assumptions'!$B$20,"Yes","NO") -> Yes
A27: Year 5 | B27: =B26*(1+'1. Cover & Assumptions'!$B$16) -> 2745.1875 | C27: =B27/'1. Cover & Assumptions'!$B$20 -> 0.25981332 | D27: =IF(B27<'1. Cover & Assumptions'!$B$20,"Yes","NO") -> Yes
A28: Year 6 | B28: =B27*(1+'1. Cover & Assumptions'!$B$16) -> 3019.7063 | C28: =B28/'1. Cover & Assumptions'!$B$20 -> 0.28579465 | D28: =IF(B28<'1. Cover & Assumptions'!$B$20,"Yes","NO") -> Yes
A29: Year 7 | B29: =B28*(1+'1. Cover & Assumptions'!$B$16) -> 3321.6769 | C29: =B29/'1. Cover & Assumptions'!$B$20 -> 0.31437411 | D29: =IF(B29<'1. Cover & Assumptions'!$B$20,"Yes","NO") -> Yes
A30: Year 8 | B30: =B29*(1+'1. Cover & Assumptions'!$B$16) -> 3653.8446 | C30: =B30/'1. Cover & Assumptions'!$B$20 -> 0.34581152 | D30: =IF(B30<'1. Cover & Assumptions'!$B$20,"Yes","NO") -> Yes
A31: Year 9 | B31: =B30*(1+'1. Cover & Assumptions'!$B$16) -> 4019.229 | C31: =B31/'1. Cover & Assumptions'!$B$20 -> 0.38039268 | D31: =IF(B31<'1. Cover & Assumptions'!$B$20,"Yes","NO") -> Yes
A32: Year 10 | B32: =B31*(1+'1. Cover & Assumptions'!$B$16) -> 4421.1519 | C32: =B32/'1. Cover & Assumptions'!$B$20 -> 0.41843194 | D32: =IF(B32<'1. Cover & Assumptions'!$B$20,"Yes","NO") -> Yes

Sheet 9. Additional Costs Checklist
A1: ADDITIONAL COSTS NOT IN ORIGINAL BREAKEVEN MODEL
A3: Each item below has been added to Sheet 4 (Year 1 Proforma) under 'League/Franchise/Corp Overhead'. Use this list as a checkpoint.
A5: Category | B5: Y1 Estimate | C5: Why it matters / risk if omitted
A6: CoFL annual franchise fee | B6: 50000 | C6: League membership; required to operate
A7: Legal setup (one-time) | B7: 7500 | C7: LLC formation, contracts, league agreements, IP
A8: Ongoing accounting / bookkeeping | B8: 9000 | C8: Monthly close, payroll, sales tax, 1099s
A9: General liability insurance | B9: 18000 | C9: Crowd injury, slip-and-fall claims
A10: Player accident & workers' comp | B10: 22000 | C10: Required - players get hurt
A11: Director & Officer (D&O) | B11: 5000 | C11: Protects board / ownership group
A12: Marketing & advertising | B12: 24000 | C12: Drives attendance & sponsor ROI
A13: Website + ticketing platform | B13: 6000 | C13: Hosting, maintenance, ticket platform fees
A14: Payment processing (3% of card revenue) | B14: ~$3-5K | C14: Stripe/Square fees on ticket+merch+conc
A15: Background checks | B15: 3000 | C15: Required for staff / coaches / volunteers
A16: Player meals / training table | B16: 27000 | C16: Performance + retention
A17: Medical supplies & training room | B17: 5000 | C17: Tape, ice, baseline kits
A18: Concussion baseline testing | B18: 4500 | C18: Liability protection
A19: Field paint, chalk, line marking | B19: 2500 | C19: Game-day field prep
A20: Towel & laundry service | B20: 3000 | C20: 60+ uniform sets
A21: Photography / videography | B21: 2250 | C21: Marketing assets, sponsor decks
A22: Livestream production | B22: 4500 | C22: Out-of-market fans, sponsor value
A23: Statistician / scorekeeper | B23: 600 | C23: Required for league record-keeping
A24: PR / publicist retainer | B24: 18000 | C24: Media relations, story placement
A25: Player recruitment / tryouts | B25: 8000 | C25: Roster construction
A26: League dues / assessments | B26: 5000 | C26: Beyond franchise fee
... A32: Bank fees & merchant account | B32: 1800 | C32: Operating account fees
A33: Contingency (5% of base opex) | B33: Modeled | C33: Buffer for surprises
A34: Stadium concession buyout (if Tyler ISD declines) | B34: 750 | C34: $250/day x 3 home games
A35: EMT / on-site medical (per game) | B35: 1080 | C35: $60/hr x 6 hrs x 3 games
A36: PA announcer & game ops | B36: 1800 | C36: Polish for fan experience
A37: Trademark filing | B37: 2000 | C37: Protect team name & marks
A38: WeFunder broker-dealer fee (~6.5%) | B38: 6500 | C38: On $100K raise = ~$6.5K

Sheet 10. Required Employees
A1: REQUIRED EMPLOYEES & STAFFING PLAN
A3: GAME-DAY STAFFING (PER HOME GAME)
A4: Role | B4: Headcount | C4: Rate / hr | D4: Hours / game | E4: Notes
A5: Field supervisor | B5: 1 | C5: 25 | D5: 6 | E5: Stadium-required Tyler ISD staff
A6: Custodians | B6: 2 | C6: 25 | D6: 6 | E6: Stadium-required Tyler ISD staff
A7: Security officers | B7: 8 | C7: 30 | D7: 6 | E7: Capacity-based; ~1 per 235 attendees
A8: EMT / medical standby | B8: 2 | C8: 60 | D8: 6 | E8: Industry standard
A9: Scoreboard / clock op | B9: 1 | C9: 35 | D9: 6 | E9: Stadium-required
A10: PA announcer | B10: 1 | C10: 150 | D10: 4 | E10: Flat fee per game
A11: Ticket takers / ushers | B11: 6 | C11: 15 | D11: 6 | E11: Game-day workers
A12: Officials (refs) | B12: 6 | C12: 125 | D12: 3 | E12: Crew of 6 per game
A13: Equipment manager | B13: 1 | C13: 500 | D13: 1 | E13: Per-game stipend basis
A14: Athletic trainers | B14: 2 | C14: 500 | D14: 1 | E14: Stipend per week, on-site game day
A15: Coaches (HC + 6 asst) | B15: 7 | C15: Stipend | D15: Stipend | E15: Salaried/stipend - not hourly
A16: Players (active roster) | B16: 40 | C16: Stipend | D16: Stipend | E16: Per-game stipend basis
A19: FRONT OFFICE / FULL-TIME STAFFING
A20: General Manager | B20: 1 | C20: 65000 | D20: FT | E20: Builds program; investor / sponsor face
A21: Director of Marketing & Sales | B21: 1 | C21: 50000 | D21: FT | E21: Drives ticket + sponsor revenue
A22: Operations / Game-Day Coordinator | B22: 1 | C22: 40000 | D22: PT/FT | E22: Handles vendor, league, stadium logistics
A23: Bookkeeper / Office Admin | B23: 1 | C23: 18000 | D23: PT | E23: 10-15 hrs/wk
A24: Social Media / Content (contract) | B24: 1 | C24: 12000 | D24: Contract | E24: Year-round content + game day
